<?xml version="1.0"?>
<robot xmlns:xacro="http://wiki.ros.org/xacro">
  <!--
    UR 机器人系列的基础 xacro 宏。

    注意：该文件不是 URDF，不能直接作为展开后的 '.urdf' 文件加载。
    如需完整模型，请使用顶层 '.xacro' 文件，并仍然通过 xacro 命令处理。

    本文件描述 UR 机器人的基础运动链，再通过不同配置文件参数化为
    UR3(e)、UR5(e)、UR10(e)、UR16e 等具体型号。

    注意：默认运动学参数（如连杆长度、坐标系位置、偏移等）不对应任何
    具体机器人，只是默认值。TF（robot_state_publisher）中的正运动学结果
    与示教器报告值之间一定会存在非零偏差。

    若需要准确且针对具体机器人的坐标变换，'kinematics_parameters_file'
    参数必须指向包含目标机器人标定值的 .yaml 文件。

    如果使用 UniversalRobots/Universal_Robots_ROS_Driver，请按该仓库
    README 中的步骤从控制器提取运动学校准数据，并生成所需 .yaml 文件。

    yaml 配置迁移主要作者：Ludovic Delval。

    早期版本贡献者（排名不分先后）

     - Denis Stogl
     - Lovro Ivanov
     - Felix Messmer
     - Kelsey Hawkins
     - Wim Meeussen
     - Shaun Edwards
     - Nadia Hammoudeh Garcia
     - Dave Hershberger
     - G. vd. Hoorn
     - Philip Long
     - Dave Coleman
     - Miguel Prada
     - Mathias Luedtke
     - Marcel Schnirring
     - Felix von Drigalski
     - Felix Exner
     - Jimmy Da Silva
     - Ajit Krisshna N L
     - Muhammad Asif Rana
  -->

  <xacro:include filename="$(find ur_description)/urdf/inc/ur_transmissions.xacro" />
  <xacro:include filename="$(find ur_description)/urdf/inc/ur_common.xacro" />

  <xacro:macro name="ur_robot" params="
    name
    tf_prefix
    parent
    *origin
    joint_limits_parameters_file
    kinematics_parameters_file
    physical_parameters_file
    visual_parameters_file
    generate_ros2_control_tag:=true
    transmission_hw_interface:=hardware_interface/PositionJointInterface
    safety_limits:=false
    safety_pos_margin:=0.15
    safety_k_position:=20
    use_fake_hardware:=false
    fake_sensor_commands:=false
    sim_gazebo:=false
    sim_ignition:=false
    headless_mode:=false
    initial_positions:=${dict(shoulder_pan_joint=0.0,shoulder_lift_joint=-1.57,elbow_joint=0.0,wrist_1_joint=-1.57,wrist_2_joint=0.0,wrist_3_joint=0.0)}
    use_tool_communication:=false
    tool_voltage:=0
    tool_parity:=0
    tool_baud_rate:=115200
    tool_stop_bits:=1
    tool_rx_idle_chars:=1.5
    tool_tx_idle_chars:=3.5
    tool_device_name:=/tmp/ttyUR
    tool_tcp_port:=54321
    robot_ip:=0.0.0.0
    script_filename:=unused_in_simulation
    output_recipe_filename:=unused_in_simulation
    input_recipe_filename:=unused_in_simulation
    reverse_port:=50001
    script_sender_port:=50002
    reverse_ip:=0.0.0.0
    script_command_port:=50004
    trajectory_port:=50003
    non_blocking_read:=true
    keep_alive_count:=2"

    >

    <!-- 从提供的 .yaml 文件加载配置数据 -->
    <xacro:read_model_data
      joint_limits_parameters_file="${joint_limits_parameters_file}"
      kinematics_parameters_file="${kinematics_parameters_file}"
      physical_parameters_file="${physical_parameters_file}"
      visual_parameters_file="${visual_parameters_file}"
      force_abs_paths="${sim_gazebo or sim_ignition}"/>

    <xacro:property name="joint_dynamics_damping" value="${1.0 if sim_gazebo or sim_ignition else 0.0}"/>
    <xacro:property name="joint_dynamics_friction" value="${0.05 if sim_gazebo or sim_ignition else 0.0}"/>


    <xacro:if value="${generate_ros2_control_tag}">
      <!-- 引入 ros2_control 描述 -->
      <xacro:include filename="$(find ur_description)/urdf/ur.ros2_control.xacro" />
      <!-- 创建 ros2_control 实例 -->
      <xacro:ur_ros2_control
        name="${name}"
        use_fake_hardware="${use_fake_hardware}"
        initial_positions="${initial_positions}"
        fake_sensor_commands="${fake_sensor_commands}"
        headless_mode="${headless_mode}"
        sim_gazebo="${sim_gazebo}"
        sim_ignition="${sim_ignition}"
        script_filename="${script_filename}"
        output_recipe_filename="${output_recipe_filename}"
        input_recipe_filename="${input_recipe_filename}"
        tf_prefix="${tf_prefix}"
        hash_kinematics="${kinematics_hash}"
        robot_ip="${robot_ip}"
        use_tool_communication="${use_tool_communication}"
        tool_voltage="${tool_voltage}"
        tool_parity="${tool_parity}"
        tool_baud_rate="${tool_baud_rate}"
        tool_stop_bits="${tool_stop_bits}"
        tool_rx_idle_chars="${tool_rx_idle_chars}"
        tool_tx_idle_chars="${tool_tx_idle_chars}"
        tool_device_name="${tool_device_name}"
        tool_tcp_port="${tool_tcp_port}"
        reverse_port="${reverse_port}"
        script_sender_port="${script_sender_port}"
        reverse_ip="${reverse_ip}"
        script_command_port="${script_command_port}"
        trajectory_port="${trajectory_port}"
        non_blocking_read="${non_blocking_read}"
        keep_alive_count="${keep_alive_count}"
        />
    </xacro:if>

    <!-- 添加 URDF transmission 元素（供 ros_control 使用） -->
    <!--<xacro:ur_arm_transmission prefix="${prefix}" hw_interface="${transmission_hw_interface}" />-->
    <!-- ros2_control transmission 尚不存在时的占位说明 -->

    <!-- 连杆：主串联链 -->
    <link name="${tf_prefix}base_link"/>
    <link name="${tf_prefix}base_link_inertia">
      <visual>
        <origin xyz="0 0 0" rpy="0 0 ${pi}"/>
        <geometry>
          <xacro:get_mesh name="base" type="visual"/>
        </geometry>
      </visual>
      <collision>
        <origin xyz="0 0 0" rpy="0 0 ${pi}"/>
        <geometry>
          <xacro:get_mesh name="base" type="collision"/>
        </geometry>
      </collision>
      <xacro:cylinder_inertial radius="${base_inertia_radius}" length="${base_inertia_length}" mass="${base_mass}">
        <origin xyz="0 0 0" rpy="0 0 0" />
      </xacro:cylinder_inertial>
    </link>
    <link name="${tf_prefix}shoulder_link">
      <visual>
        <origin xyz="0 0 0" rpy="0 0 ${pi}"/>
        <geometry>
          <xacro:get_mesh name="shoulder" type="visual"/>
        </geometry>
      </visual>
      <collision>
        <origin xyz="0 0 0" rpy="0 0 ${pi}"/>
        <geometry>
          <xacro:get_mesh name="shoulder" type="collision"/>
        </geometry>
      </collision>
      <inertial>
        <mass value="${shoulder_mass}"/>
        <origin rpy="${shoulder_inertia_rotation}" xyz="${shoulder_cog}"/>
        <inertia
            ixx="${shoulder_inertia_ixx}"
            ixy="${shoulder_inertia_ixy}"
            ixz="${shoulder_inertia_ixz}"
            iyy="${shoulder_inertia_iyy}"
            iyz="${shoulder_inertia_iyz}"
            izz="${shoulder_inertia_izz}"
        />
      </inertial>    </link>
    <link name="${tf_prefix}upper_arm_link">
      <visual>
        <origin xyz="0 0 ${shoulder_offset}" rpy="${pi/2} 0 ${-pi/2}"/>
        <geometry>
          <xacro:get_mesh name="upper_arm" type="visual"/>
        </geometry>
      </visual>
      <collision>
        <origin xyz="0 0 ${shoulder_offset}" rpy="${pi/2} 0 ${-pi/2}"/>
        <geometry>
          <xacro:get_mesh name="upper_arm" type="collision"/>
        </geometry>
      </collision>
      <inertial>
        <mass value="${upper_arm_mass}"/>
        <origin rpy="${upper_arm_inertia_rotation}" xyz="${upper_arm_cog}"/>
        <inertia
            ixx="${upper_arm_inertia_ixx}"
            ixy="${upper_arm_inertia_ixy}"
            ixz="${upper_arm_inertia_ixz}"
            iyy="${upper_arm_inertia_iyy}"
            iyz="${upper_arm_inertia_iyz}"
            izz="${upper_arm_inertia_izz}"
        />
      </inertial>
    </link>
    <link name="${tf_prefix}forearm_link">
      <visual>
        <origin xyz="0 0 ${elbow_offset}" rpy="${pi/2} 0 ${-pi/2}"/>
        <geometry>
          <xacro:get_mesh name="forearm" type="visual"/>
        </geometry>
      </visual>
      <collision>
        <origin xyz="0 0 ${elbow_offset}" rpy="${pi/2} 0 ${-pi/2}"/>
        <geometry>
          <xacro:get_mesh name="forearm" type="collision"/>
        </geometry>
      </collision>
      <inertial>
        <mass value="${forearm_mass}"/>
        <origin rpy="${forearm_inertia_rotation}" xyz="${forearm_cog}"/>
        <inertia
            ixx="${forearm_inertia_ixx}"
            ixy="${forearm_inertia_ixy}"
            ixz="${forearm_inertia_ixz}"
            iyy="${forearm_inertia_iyy}"
            iyz="${forearm_inertia_iyz}"
            izz="${forearm_inertia_izz}"
        />
      </inertial>
    </link>
    <link name="${tf_prefix}wrist_1_link">
	  <xacro:get_visual_params name="wrist_1" type="visual_offset"/>
      <visual>
      	<origin xyz="0 0 ${visual_params}" rpy="${pi/2} 0 0"/>
        <geometry>
          <xacro:get_mesh name="wrist_1" type="visual"/>
        </geometry>
      </visual>
      <collision>
        <origin xyz="0 0 ${visual_params}" rpy="${pi/2} 0 0"/>
        <geometry>
          <xacro:get_mesh name="wrist_1" type="collision"/>
        </geometry>
      </collision>
      <inertial>
        <mass value="${wrist_1_mass}"/>
        <origin rpy="${wrist_1_inertia_rotation}" xyz="${wrist_1_cog}"/>
        <inertia
            ixx="${wrist_1_inertia_ixx}"
            ixy="${wrist_1_inertia_ixy}"
            ixz="${wrist_1_inertia_ixz}"
            iyy="${wrist_1_inertia_iyy}"
            iyz="${wrist_1_inertia_iyz}"
            izz="${wrist_1_inertia_izz}"
        />
      </inertial>
    </link>
    <link name="${tf_prefix}wrist_2_link">
          <xacro:get_visual_params name="wrist_2" type="visual_offset"/>
      <visual>
        <origin xyz="0 0 ${visual_params}" rpy="0 0 0"/>
        <geometry>
          <xacro:get_mesh name="wrist_2" type="visual"/>
        </geometry>
      </visual>
      <collision>
        <origin xyz="0 0 ${visual_params}" rpy="0 0 0"/>
        <geometry>
          <xacro:get_mesh name="wrist_2" type="collision"/>
        </geometry>
      </collision>
      <inertial>
        <mass value="${wrist_2_mass}"/>
        <origin rpy="${wrist_2_inertia_rotation}" xyz="${wrist_2_cog}"/>
        <inertia
            ixx="${wrist_2_inertia_ixx}"
            ixy="${wrist_2_inertia_ixy}"
            ixz="${wrist_2_inertia_ixz}"
            iyy="${wrist_2_inertia_iyy}"
            iyz="${wrist_2_inertia_iyz}"
            izz="${wrist_2_inertia_izz}"
        />
      </inertial>
    </link>
    <link name="${tf_prefix}wrist_3_link">
      <!-- TODO：所有 wrist_3 网格都带有 visual_offset_xyz 标签后删除此处 -->
      <xacro:get_visual_params name="wrist_3" type="visual_offset_xyz"/>
      <xacro:property name="mesh_offset" value="${visual_params}" scope="parent"/>

      <xacro:if value="${visual_params == ''}">
        <xacro:get_visual_params name="wrist_3" type="visual_offset"/>
        <xacro:property name="mesh_offset" value="0 0 ${visual_params}" scope="parent"/>
      </xacro:if>
      <visual>
        <origin xyz="${mesh_offset}" rpy="${pi/2} 0 0"/>
        <geometry>
          <xacro:get_mesh name="wrist_3" type="visual"/>
        </geometry>
      </visual>
      <collision>
        <origin xyz="${mesh_offset}" rpy="${pi/2} 0 0"/>
        <geometry>
          <xacro:get_mesh name="wrist_3" type="collision"/>
        </geometry>
      </collision>
      <inertial>
        <mass value="${wrist_3_mass}"/>
        <origin rpy="${wrist_3_inertia_rotation}" xyz="${wrist_3_cog}"/>
        <inertia
            ixx="${wrist_3_inertia_ixx}"
            ixy="${wrist_3_inertia_ixy}"
            ixz="${wrist_3_inertia_ixz}"
            iyy="${wrist_3_inertia_iyy}"
            iyz="${wrist_3_inertia_iyz}"
            izz="${wrist_3_inertia_izz}"
        />
      </inertial>
    </link>

    <!-- base_joint 将 base_link 固定到环境坐标系 -->
    <joint name="${tf_prefix}base_joint" type="fixed">
      <xacro:insert_block name="origin" />
      <parent link="${parent}" />
      <child link="${tf_prefix}base_link" />
    </joint>

    <!-- 关节：主串联链 -->
    <joint name="${tf_prefix}base_link-base_link_inertia" type="fixed">
      <parent link="${tf_prefix}base_link" />
      <child link="${tf_prefix}base_link_inertia" />
      <!-- 'base_link' 遵循 REP-103（X+ 向前），而机器人/控制器内部坐标系的
           X+ 指向后方。这里通过 'base_link' 与 'base_link_inertia'（虚拟连杆/
           坐标系）之间的关节引入绕 Z 轴 pi 弧度的必要旋转。
      -->
      <origin xyz="0 0 0" rpy="0 0 ${pi}" />
    </joint>
    <joint name="${tf_prefix}shoulder_pan_joint" type="revolute">
      <parent link="${tf_prefix}base_link_inertia" />
      <child link="${tf_prefix}shoulder_link" />
      <origin xyz="${shoulder_x} ${shoulder_y} ${shoulder_z}" rpy="${shoulder_roll} ${shoulder_pitch} ${shoulder_yaw}" />
      <axis xyz="0 0 1" />
      <limit lower="${shoulder_pan_lower_limit}" upper="${shoulder_pan_upper_limit}"
        effort="${shoulder_pan_effort_limit}" velocity="${shoulder_pan_velocity_limit}"/>
      <xacro:if value="${safety_limits}">
         <safety_controller soft_lower_limit="${shoulder_pan_lower_limit + safety_pos_margin}" soft_upper_limit="${shoulder_pan_upper_limit - safety_pos_margin}" k_position="${safety_k_position}" k_velocity="0.0"/>
      </xacro:if>
      <dynamics damping="${joint_dynamics_damping}" friction="${joint_dynamics_friction}"/>
    </joint>
    <joint name="${tf_prefix}shoulder_lift_joint" type="revolute">
      <parent link="${tf_prefix}shoulder_link" />
      <child link="${tf_prefix}upper_arm_link" />
      <origin xyz="${upper_arm_x} ${upper_arm_y} ${upper_arm_z}" rpy="${upper_arm_roll} ${upper_arm_pitch} ${upper_arm_yaw}" />
      <axis xyz="0 0 1" />
      <limit lower="${shoulder_lift_lower_limit}" upper="${shoulder_lift_upper_limit}"
        effort="${shoulder_lift_effort_limit}" velocity="${shoulder_lift_velocity_limit}"/>
      <xacro:if value="${safety_limits}">
         <safety_controller soft_lower_limit="${shoulder_lift_lower_limit + safety_pos_margin}" soft_upper_limit="${shoulder_lift_upper_limit - safety_pos_margin}" k_position="${safety_k_position}" k_velocity="0.0"/>
      </xacro:if>
      <dynamics damping="${joint_dynamics_damping}" friction="${joint_dynamics_friction}"/>
    </joint>
    <joint name="${tf_prefix}elbow_joint" type="revolute">
      <parent link="${tf_prefix}upper_arm_link" />
      <child link="${tf_prefix}forearm_link" />
      <origin xyz="${forearm_x} ${forearm_y} ${forearm_z}" rpy="${forearm_roll} ${forearm_pitch} ${forearm_yaw}" />
      <axis xyz="0 0 1" />
      <limit lower="${elbow_joint_lower_limit}" upper="${elbow_joint_upper_limit}"
        effort="${elbow_joint_effort_limit}" velocity="${elbow_joint_velocity_limit}"/>
      <xacro:if value="${safety_limits}">
         <safety_controller soft_lower_limit="${elbow_joint_lower_limit + safety_pos_margin}" soft_upper_limit="${elbow_joint_upper_limit - safety_pos_margin}" k_position="${safety_k_position}" k_velocity="0.0"/>
      </xacro:if>
      <dynamics damping="${joint_dynamics_damping}" friction="${joint_dynamics_friction}"/>
    </joint>
    <joint name="${tf_prefix}wrist_1_joint" type="revolute">
      <parent link="${tf_prefix}forearm_link" />
      <child link="${tf_prefix}wrist_1_link" />
      <origin xyz="${wrist_1_x} ${wrist_1_y} ${wrist_1_z}" rpy="${wrist_1_roll} ${wrist_1_pitch} ${wrist_1_yaw}" />
      <axis xyz="0 0 1" />
      <limit lower="${wrist_1_lower_limit}" upper="${wrist_1_upper_limit}"
        effort="${wrist_1_effort_limit}" velocity="${wrist_1_velocity_limit}"/>
      <xacro:if value="${safety_limits}">
         <safety_controller soft_lower_limit="${wrist_1_lower_limit + safety_pos_margin}" soft_upper_limit="${wrist_1_upper_limit - safety_pos_margin}" k_position="${safety_k_position}" k_velocity="0.0"/>
      </xacro:if>
      <dynamics damping="${joint_dynamics_damping}" friction="${joint_dynamics_friction}"/>
    </joint>
    <joint name="${tf_prefix}wrist_2_joint" type="revolute">
      <parent link="${tf_prefix}wrist_1_link" />
      <child link="${tf_prefix}wrist_2_link" />
      <origin xyz="${wrist_2_x} ${wrist_2_y} ${wrist_2_z}" rpy="${wrist_2_roll} ${wrist_2_pitch} ${wrist_2_yaw}" />
      <axis xyz="0 0 1" />
      <limit lower="${wrist_2_lower_limit}" upper="${wrist_2_upper_limit}"
             effort="${wrist_2_effort_limit}" velocity="${wrist_2_velocity_limit}"/>
      <xacro:if value="${safety_limits}">
         <safety_controller soft_lower_limit="${wrist_2_lower_limit + safety_pos_margin}" soft_upper_limit="${wrist_2_upper_limit - safety_pos_margin}" k_position="${safety_k_position}" k_velocity="0.0"/>
      </xacro:if>
      <dynamics damping="${joint_dynamics_damping}" friction="${joint_dynamics_friction}"/>
    </joint>
    <joint name="${tf_prefix}wrist_3_joint" type="${wrist_3_joint_type}">
      <parent link="${tf_prefix}wrist_2_link" />
      <child link="${tf_prefix}wrist_3_link" />
      <origin xyz="${wrist_3_x} ${wrist_3_y} ${wrist_3_z}" rpy="${wrist_3_roll} ${wrist_3_pitch} ${wrist_3_yaw}" />
      <axis xyz="0 0 1" />
      <xacro:if value="${wrist_3_joint_type != 'continuous'}">
        <limit lower="${wrist_3_lower_limit}" upper="${wrist_3_upper_limit}"
          effort="${wrist_3_effort_limit}" velocity="${wrist_3_velocity_limit}"/>
        <xacro:if value="${safety_limits}">
          <safety_controller soft_lower_limit="${wrist_3_lower_limit + safety_pos_margin}" soft_upper_limit="${wrist_3_upper_limit - safety_pos_margin}" k_position="${safety_k_position}" k_velocity="0.0"/>
        </xacro:if>
      </xacro:if>
      <xacro:unless value="${wrist_3_joint_type != 'continuous'}">
        <limit effort="${wrist_3_effort_limit}" velocity="${wrist_3_velocity_limit}"/>
        <xacro:if value="${safety_limits}">
          <safety_controller k_position="${safety_k_position}" k_velocity="0.0"/>
        </xacro:if>
      </xacro:unless>
      <dynamics damping="${joint_dynamics_damping}" friction="${joint_dynamics_friction}"/>
    </joint>

    <link name="${tf_prefix}ft_frame"/>
    <joint name="${tf_prefix}wrist_3_link-ft_frame" type="fixed">
      <parent link="${tf_prefix}wrist_3_link"/>
      <child link="${tf_prefix}ft_frame"/>
      <origin xyz="0 0 0" rpy="${pi} 0 0"/>
    </joint>

    <!-- ROS-Industrial 'base' 坐标系：base_link 到 UR 'Base' 坐标系的变换 -->
    <link name="${tf_prefix}base"/>
    <joint name="${tf_prefix}base_link-base_fixed_joint" type="fixed">
      <!-- 注意这里绕 Z 轴旋转 pi 弧度：base_link 遵循 REP-103
           （X+ 向前、Y+ 向左、Z+ 向上），因此需要该旋转才能让 'base'
           正确对齐 UR 控制器中的 'Base' 坐标系。
      -->
      <origin xyz="0 0 0" rpy="0 0 ${pi}"/>
      <parent link="${tf_prefix}base_link"/>
      <child link="${tf_prefix}base"/>
    </joint>

    <!-- ROS-Industrial 'flange' 坐标系：末端执行器模型的安装点 -->
    <link name="${tf_prefix}flange" />
    <joint name="${tf_prefix}wrist_3-flange" type="fixed">
      <parent link="${tf_prefix}wrist_3_link" />
      <child link="${tf_prefix}flange" />
      <origin xyz="0 0 0" rpy="0 ${-pi/2.0} ${-pi/2.0}" />
    </joint>

    <!-- ROS-Industrial 'tool0' 坐标系：全零工具坐标系 -->
    <link name="${tf_prefix}tool0"/>
    <joint name="${tf_prefix}flange-tool0" type="fixed">
      <!-- 默认工具坐标系：X+ 向左，Y+ 向上，Z+ 向前 -->
      <origin xyz="0 0 0" rpy="${pi/2.0} 0 ${pi/2.0}"/>
      <parent link="${tf_prefix}flange"/>
      <child link="${tf_prefix}tool0"/>
    </joint>

  </xacro:macro>
</robot>
